Script started on Wed Sep 11 11:46:56 2024
[1m[7m%[27m[1m[0m                                                                                                                                                                                [0m[27m[24m[Jabdullaazimov@MacBook-Pro-Abdulla INSAN % [K[?2004h brew install ngrok/ngrok/ngrok[20Dpython manage.py runserver     [26D brew install ngrok/ngrok/ngrok[31D                               [31D brew install ngrok/ngrok/ngrok[31D                               [31D[7mscript venv/bin/actvate [27m[24D[27ms[27mc[27mr[27mi[27mp[27mt[27m [27mv[27me[27mn[27mv[27m/[27mb[27mi[27mn[27m/[27ma[27mc[27mt[27mv[27ma[27mt[27me[27m                     s  aactivate [?2004l
zsh: command not found: activate
[1m[7m%[27m[1m[0m                                                                                                                                                                                [0m[27m[24m[Jabdullaazimov@MacBook-Pro-Abdulla INSAN % [K[?2004h[7mabdullaazimov@MacBook-Pro-Abdulla INSAN % scripts venv/bin/actvate [27m
[7mzsh: command not found: scripts[27m[K
[7mabdullaazimov@MacBook-Pro-Abdulla INSAN % script venv/bin/actvate [27m[K
[7mScript started, output file is venv/bin/actvate[27m[K
[7mabdullaazimov@MacBook-Pro-Abdulla INSAN % activate                       [27m[K
[7mzsh: command not found: activate[27m[K
[K[6A[42C[27ma[27mb[27md[27mu[27ml[27ml[27ma[27ma[27mz[27mi[27mm[27mo[27mv[27m@[27mM[27ma[27mc[27mB[27mo[27mo[27mk[27m-[27mP[27mr[27mo[27m-[27mA[27mb[27md[27mu[27ml[27ml[27ma[27m [27mI[27mN[27mS[27mA[27mN[27m [27m%[27m [27ms[27mc[27mr[27mi[27mp[27mt[27ms[27m [27mv[27me[27mn[27mv[27m/[27mb[27mi[27mn[27m/[27ma[27mc[27mt[27mv[27ma[27mt[27me[27m [1B[27mz[27ms[27mh[27m:[27m [27mc[27mo[27mm[27mm[27ma[27mn[27md[27m [27mn[27mo[27mt[27m [27mf[27mo[27mu[27mn[27md[27m:[27m [27ms[27mc[27mr[27mi[27mp[27mt[27ms[1B[27ma[27mb[27md[27mu[27ml[27ml[27ma[27ma[27mz[27mi[27mm[27mo[27mv[27m@[27mM[27ma[27mc[27mB[27mo[27mo[27mk[27m-[27mP[27mr[27mo[27m-[27mA[27mb[27md[27mu[27ml[27ml[27ma[27m [27mI[27mN[27mS[27mA[27mN[27m [27m%[27m [27ms[27mc[27mr[27mi[27mp[27mt[27m [27mv[27me[27mn[27mv[27m/[27mb[27mi[27mn[27m/[27ma[27mc[27mt[27mv[27ma[27mt[27me[K[1B[27mS[27mc[27mr[27mi[27mp[27mt[27m [27ms[27mt[27ma[27mr[27mt[27me[27md[27m,[27m [27mo[27mu[27mt[27mp[27mu[27mt[27m [27mf[27mi[27ml[27me[27m [27mi[27ms[27m [27mv[27me[27mn[27mv[27m/[27mb[27mi[27mn[27m/[27ma[27mc[27mt[27mv[27ma[27mt[27me[1B[27ma[27mb[27md[27mu[27ml[27ml[27ma[27ma[27mz[27mi[27mm[27mo[27mv[27m@[27mM[27ma[27mc[27mB[27mo[27mo[27mk[27m-[27mP[27mr[27mo[27m-[27mA[27mb[27md[27mu[27ml[27ml[27ma[27m [27mI[27mN[27mS[27mA[27mN[27m [27m%[27m [27ma[27mc[27mt[27mi[27mv[27ma[27mt[27me[K[1B[27mz[27ms[27mh[27m:[27m [27mc[27mo[27mm[27mm[27ma[27mn[27md[27m [27mn[27mo[27mt[27m [27mf[27mo[27mu[27mn[27md[27m:[27m [27ma[27mc[27mt[27mi[27mv[27ma[27mt[27me[1B[K[A[32C    [?2004l[1Bzsh: command not found: abdullaazimov@MacBook-Pro-Abdulla
zsh: command not found: zsh:
zsh: command not found: abdullaazimov@MacBook-Pro-Abdulla
Script started, output file is started,
Script: output: No such file or directory

Script done, output file is started,
zsh: command not found: abdullaazimov@MacBook-Pro-Abdulla
zsh: command not found: zsh:
[1m[7m%[27m[1m[0m                                                                                                                                                                                [0m[27m[24m[Jabdullaazimov@MacBook-Pro-Abdulla INSAN % [K[?2004h]]clear[?2004l
zsh: command not found: ]clear
[1m[7m%[27m[1m[0m                                                                                                                                                                                [0m[27m[24m[Jabdullaazimov@MacBook-Pro-Abdulla INSAN % [K[?2004hcclear[?2004l
[3J[H[2J[1m[7m%[27m[1m[0m                                                                                                                                                                                [0m[27m[24m[Jabdullaazimov@MacBook-Pro-Abdulla INSAN % [K[?2004hsscrip   s  ssoursc  ce   ce   ser   venv /bin /activate [?2004l
zsh: command not found: sourse
[1m[7m%[27m[1m[0m                                                                                                                                                                                [0m[27m[24m[Jabdullaazimov@MacBook-Pro-Abdulla INSAN % [K[?2004hsourse venv/bin/activate[P[19C [20Dce venv/bin/activate[19D[?2004l
[1m[7m%[27m[1m[0m                                                                                                                                                                                [0m[27m[24m[J(venv) abdullaazimov@MacBook-Pro-Abdulla INSAN % [K[?2004hppython manage .py runserver [?2004l
Watching for file changes with StatReloader
Performing system checks...

System check identified no issues (0 silenced).
September 11, 2024 - 06:48:32
Django version 5.1.1, using settings 'Insan.settings'
Starting development server at http://127.0.0.1:8000/
Quit the server with CONTROL-C.

Invalid HTTP_HOST header: '42ff-188-113-234-184.ngrok-free.app'. You may need to add '42ff-188-113-234-184.ngrok-free.app' to ALLOWED_HOSTS.
Traceback (most recent call last):
  File "/Users/abdullaazimov/Desktop/PROJECTS/INSAN/venv/lib/python3.10/site-packages/django/core/handlers/exception.py", line 55, in inner
    response = get_response(request)
  File "/Users/abdullaazimov/Desktop/PROJECTS/INSAN/venv/lib/python3.10/site-packages/django/utils/deprecation.py", line 128, in __call__
    response = self.process_request(request)
  File "/Users/abdullaazimov/Desktop/PROJECTS/INSAN/venv/lib/python3.10/site-packages/django/middleware/common.py", line 48, in process_request
    host = request.get_host()
  File "/Users/abdullaazimov/Desktop/PROJECTS/INSAN/venv/lib/python3.10/site-packages/django/http/request.py", line 151, in get_host
    raise DisallowedHost(msg)
django.core.exceptions.DisallowedHost: Invalid HTTP_HOST header: '42ff-188-113-234-184.ngrok-free.app'. You may need to add '42ff-188-113-234-184.ngrok-free.app' to ALLOWED_HOSTS.
Bad Request: /
[11/Sep/2024 06:50:53] [31;1m"GET / HTTP/1.1" 400 64236[0m
Invalid HTTP_HOST header: '42ff-188-113-234-184.ngrok-free.app'. You may need to add '42ff-188-113-234-184.ngrok-free.app' to ALLOWED_HOSTS.
Traceback (most recent call last):
  File "/Users/abdullaazimov/Desktop/PROJECTS/INSAN/venv/lib/python3.10/site-packages/django/core/handlers/exception.py", line 55, in inner
    response = get_response(request)
  File "/Users/abdullaazimov/Desktop/PROJECTS/INSAN/venv/lib/python3.10/site-packages/django/utils/deprecation.py", line 128, in __call__
    response = self.process_request(request)
  File "/Users/abdullaazimov/Desktop/PROJECTS/INSAN/venv/lib/python3.10/site-packages/django/middleware/common.py", line 48, in process_request
    host = request.get_host()
  File "/Users/abdullaazimov/Desktop/PROJECTS/INSAN/venv/lib/python3.10/site-packages/django/http/request.py", line 151, in get_host
    raise DisallowedHost(msg)
django.core.exceptions.DisallowedHost: Invalid HTTP_HOST header: '42ff-188-113-234-184.ngrok-free.app'. You may need to add '42ff-188-113-234-184.ngrok-free.app' to ALLOWED_HOSTS.
Bad Request: /
[11/Sep/2024 06:50:53] [31;1m"GET / HTTP/1.1" 400 64236[0m
Invalid HTTP_HOST header: '42ff-188-113-234-184.ngrok-free.app'. You may need to add '42ff-188-113-234-184.ngrok-free.app' to ALLOWED_HOSTS.
Traceback (most recent call last):
  File "/Users/abdullaazimov/Desktop/PROJECTS/INSAN/venv/lib/python3.10/site-packages/django/core/handlers/exception.py", line 55, in inner
    response = get_response(request)
  File "/Users/abdullaazimov/Desktop/PROJECTS/INSAN/venv/lib/python3.10/site-packages/django/utils/deprecation.py", line 128, in __call__
    response = self.process_request(request)
  File "/Users/abdullaazimov/Desktop/PROJECTS/INSAN/venv/lib/python3.10/site-packages/django/middleware/common.py", line 48, in process_request
    host = request.get_host()
  File "/Users/abdullaazimov/Desktop/PROJECTS/INSAN/venv/lib/python3.10/site-packages/django/http/request.py", line 151, in get_host
    raise DisallowedHost(msg)
django.core.exceptions.DisallowedHost: Invalid HTTP_HOST header: '42ff-188-113-234-184.ngrok-free.app'. You may need to add '42ff-188-113-234-184.ngrok-free.app' to ALLOWED_HOSTS.
Bad Request: /
[11/Sep/2024 06:52:27] [31;1m"GET / HTTP/1.1" 400 64080[0m
Invalid HTTP_HOST header: '42ff-188-113-234-184.ngrok-free.app'. You may need to add '42ff-188-113-234-184.ngrok-free.app' to ALLOWED_HOSTS.
Traceback (most recent call last):
  File "/Users/abdullaazimov/Desktop/PROJECTS/INSAN/venv/lib/python3.10/site-packages/django/core/handlers/exception.py", line 55, in inner
    response = get_response(request)
  File "/Users/abdullaazimov/Desktop/PROJECTS/INSAN/venv/lib/python3.10/site-packages/django/utils/deprecation.py", line 128, in __call__
    response = self.process_request(request)
  File "/Users/abdullaazimov/Desktop/PROJECTS/INSAN/venv/lib/python3.10/site-packages/django/middleware/common.py", line 48, in process_request
    host = request.get_host()
  File "/Users/abdullaazimov/Desktop/PROJECTS/INSAN/venv/lib/python3.10/site-packages/django/http/request.py", line 151, in get_host
    raise DisallowedHost(msg)
django.core.exceptions.DisallowedHost: Invalid HTTP_HOST header: '42ff-188-113-234-184.ngrok-free.app'. You may need to add '42ff-188-113-234-184.ngrok-free.app' to ALLOWED_HOSTS.
Bad Request: /
[11/Sep/2024 06:52:47] [31;1m"GET / HTTP/1.1" 400 64080[0m
Invalid HTTP_HOST header: '42ff-188-113-234-184.ngrok-free.app'. You may need to add '42ff-188-113-234-184.ngrok-free.app' to ALLOWED_HOSTS.
Traceback (most recent call last):
  File "/Users/abdullaazimov/Desktop/PROJECTS/INSAN/venv/lib/python3.10/site-packages/django/core/handlers/exception.py", line 55, in inner
    response = get_response(request)
  File "/Users/abdullaazimov/Desktop/PROJECTS/INSAN/venv/lib/python3.10/site-packages/django/utils/deprecation.py", line 128, in __call__
    response = self.process_request(request)
  File "/Users/abdullaazimov/Desktop/PROJECTS/INSAN/venv/lib/python3.10/site-packages/django/middleware/common.py", line 48, in process_request
    host = request.get_host()
  File "/Users/abdullaazimov/Desktop/PROJECTS/INSAN/venv/lib/python3.10/site-packages/django/http/request.py", line 151, in get_host
    raise DisallowedHost(msg)
django.core.exceptions.DisallowedHost: Invalid HTTP_HOST header: '42ff-188-113-234-184.ngrok-free.app'. You may need to add '42ff-188-113-234-184.ngrok-free.app' to ALLOWED_HOSTS.
Bad Request: /
[11/Sep/2024 06:52:51] [31;1m"GET / HTTP/1.1" 400 64080[0m
Invalid HTTP_HOST header: '42ff-188-113-234-184.ngrok-free.app'. You may need to add '42ff-188-113-234-184.ngrok-free.app' to ALLOWED_HOSTS.
Traceback (most recent call last):
  File "/Users/abdullaazimov/Desktop/PROJECTS/INSAN/venv/lib/python3.10/site-packages/django/core/handlers/exception.py", line 55, in inner
    response = get_response(request)
  File "/Users/abdullaazimov/Desktop/PROJECTS/INSAN/venv/lib/python3.10/site-packages/django/utils/deprecation.py", line 128, in __call__
    response = self.process_request(request)
  File "/Users/abdullaazimov/Desktop/PROJECTS/INSAN/venv/lib/python3.10/site-packages/django/middleware/common.py", line 48, in process_request
    host = request.get_host()
  File "/Users/abdullaazimov/Desktop/PROJECTS/INSAN/venv/lib/python3.10/site-packages/django/http/request.py", line 151, in get_host
    raise DisallowedHost(msg)
django.core.exceptions.DisallowedHost: Invalid HTTP_HOST header: '42ff-188-113-234-184.ngrok-free.app'. You may need to add '42ff-188-113-234-184.ngrok-free.app' to ALLOWED_HOSTS.
Bad Request: /
[11/Sep/2024 06:52:53] [31;1m"GET / HTTP/1.1" 400 64080[0m
Invalid HTTP_HOST header: '42ff-188-113-234-184.ngrok-free.app'. You may need to add '42ff-188-113-234-184.ngrok-free.app' to ALLOWED_HOSTS.
Traceback (most recent call last):
  File "/Users/abdullaazimov/Desktop/PROJECTS/INSAN/venv/lib/python3.10/site-packages/django/core/handlers/exception.py", line 55, in inner
    response = get_response(request)
  File "/Users/abdullaazimov/Desktop/PROJECTS/INSAN/venv/lib/python3.10/site-packages/django/utils/deprecation.py", line 128, in __call__
    response = self.process_request(request)
  File "/Users/abdullaazimov/Desktop/PROJECTS/INSAN/venv/lib/python3.10/site-packages/django/middleware/common.py", line 48, in process_request
    host = request.get_host()
  File "/Users/abdullaazimov/Desktop/PROJECTS/INSAN/venv/lib/python3.10/site-packages/django/http/request.py", line 151, in get_host
    raise DisallowedHost(msg)
django.core.exceptions.DisallowedHost: Invalid HTTP_HOST header: '42ff-188-113-234-184.ngrok-free.app'. You may need to add '42ff-188-113-234-184.ngrok-free.app' to ALLOWED_HOSTS.
Bad Request: /
[11/Sep/2024 06:52:55] [31;1m"GET / HTTP/1.1" 400 64080[0m
Invalid HTTP_HOST header: '42ff-188-113-234-184.ngrok-free.app'. You may need to add '42ff-188-113-234-184.ngrok-free.app' to ALLOWED_HOSTS.
Traceback (most recent call last):
  File "/Users/abdullaazimov/Desktop/PROJECTS/INSAN/venv/lib/python3.10/site-packages/django/core/handlers/exception.py", line 55, in inner
    response = get_response(request)
  File "/Users/abdullaazimov/Desktop/PROJECTS/INSAN/venv/lib/python3.10/site-packages/django/utils/deprecation.py", line 128, in __call__
    response = self.process_request(request)
  File "/Users/abdullaazimov/Desktop/PROJECTS/INSAN/venv/lib/python3.10/site-packages/django/middleware/common.py", line 48, in process_request
    host = request.get_host()
  File "/Users/abdullaazimov/Desktop/PROJECTS/INSAN/venv/lib/python3.10/site-packages/django/http/request.py", line 151, in get_host
    raise DisallowedHost(msg)
django.core.exceptions.DisallowedHost: Invalid HTTP_HOST header: '42ff-188-113-234-184.ngrok-free.app'. You may need to add '42ff-188-113-234-184.ngrok-free.app' to ALLOWED_HOSTS.
Bad Request: /
[11/Sep/2024 06:52:57] [31;1m"GET / HTTP/1.1" 400 63943[0m
/Users/abdullaazimov/Desktop/PROJECTS/INSAN/Insan/settings.py changed, reloading.
Watching for file changes with StatReloader
Performing system checks...

System check identified no issues (0 silenced).
September 11, 2024 - 06:53:01
Django version 5.1.1, using settings 'Insan.settings'
Starting development server at http://127.0.0.1:8000/
Quit the server with CONTROL-C.

[11/Sep/2024 06:53:13] [m"GET / HTTP/1.1" 200 12068[0m
[11/Sep/2024 06:53:13] [m"GET / HTTP/1.1" 200 12068[0m
[11/Sep/2024 06:53:21] [m"GET / HTTP/1.1" 200 12068[0m
[11/Sep/2024 06:54:40] [m"GET / HTTP/1.1" 200 12068[0m
Not Found: /favicon.ico
[11/Sep/2024 06:54:42] [33m"GET /favicon.ico HTTP/1.1" 404 2228[0m
/Users/abdullaazimov/Desktop/PROJECTS/INSAN/Insan/settings.py changed, reloading.
Watching for file changes with StatReloader
Performing system checks...

System check identified no issues (0 silenced).
September 11, 2024 - 08:40:19
Django version 5.1.1, using settings 'Insan.settings'
Starting development server at http://127.0.0.1:8000/
Quit the server with CONTROL-C.

[11/Sep/2024 08:42:12] [m"GET / HTTP/1.1" 200 12068[0m
/Users/abdullaazimov/Desktop/PROJECTS/INSAN/base/urls.py changed, reloading.
Watching for file changes with StatReloader
Performing system checks...

System check identified no issues (0 silenced).
September 11, 2024 - 08:42:59
Django version 5.1.1, using settings 'Insan.settings'
Starting development server at http://127.0.0.1:8000/
Quit the server with CONTROL-C.

[11/Sep/2024 08:42:59] [m"GET / HTTP/1.1" 200 0[0m
[11/Sep/2024 08:43:00] [m"GET / HTTP/1.1" 200 0[0m
[11/Sep/2024 08:43:01] [m"GET / HTTP/1.1" 200 0[0m
[11/Sep/2024 08:43:01] [m"GET / HTTP/1.1" 200 0[0m
[11/Sep/2024 08:43:02] [m"GET / HTTP/1.1" 200 0[0m
[11/Sep/2024 08:43:02] [m"GET / HTTP/1.1" 200 0[0m
[11/Sep/2024 08:43:02] [m"GET / HTTP/1.1" 200 0[0m
[11/Sep/2024 08:43:02] [m"GET / HTTP/1.1" 200 0[0m
[11/Sep/2024 08:43:02] [m"GET / HTTP/1.1" 200 0[0m
[11/Sep/2024 08:43:19] [m"GET / HTTP/1.1" 200 0[0m
[11/Sep/2024 08:43:19] [m"GET / HTTP/1.1" 200 0[0m
[11/Sep/2024 08:43:20] [m"GET / HTTP/1.1" 200 0[0m
[11/Sep/2024 08:43:20] [m"GET / HTTP/1.1" 200 0[0m
/Users/abdullaazimov/Desktop/PROJECTS/INSAN/base/views.py changed, reloading.
Watching for file changes with StatReloader
Performing system checks...

System check identified no issues (0 silenced).
September 11, 2024 - 08:43:20
Django version 5.1.1, using settings 'Insan.settings'
Starting development server at http://127.0.0.1:8000/
Quit the server with CONTROL-C.

[11/Sep/2024 08:43:20] [m"GET / HTTP/1.1" 200 0[0m
[11/Sep/2024 08:43:21] [m"GET / HTTP/1.1" 200 0[0m
[11/Sep/2024 08:43:49] [m"GET / HTTP/1.1" 200 0[0m
[11/Sep/2024 08:43:50] [m"GET / HTTP/1.1" 200 0[0m
/Users/abdullaazimov/Desktop/PROJECTS/INSAN/Insan/urls.py changed, reloading.
Watching for file changes with StatReloader
Performing system checks...

System check identified no issues (0 silenced).
September 11, 2024 - 08:43:50
Django version 5.1.1, using settings 'Insan.settings'
Starting development server at http://127.0.0.1:8000/
Quit the server with CONTROL-C.

Not Found: /
[11/Sep/2024 08:43:50] [33m"GET / HTTP/1.1" 404 2303[0m
Not Found: /
[11/Sep/2024 08:43:50] [33m"GET / HTTP/1.1" 404 2303[0m
Not Found: /
[11/Sep/2024 08:43:51] [33m"GET / HTTP/1.1" 404 2303[0m
Not Found: /
[11/Sep/2024 08:43:51] [33m"GET / HTTP/1.1" 404 2303[0m
[11/Sep/2024 08:43:53] [32m"GET /admin/ HTTP/1.1" 302 0[0m
[11/Sep/2024 08:43:53] [m"GET /admin/login/?next=/admin/ HTTP/1.1" 200 4160[0m
[11/Sep/2024 08:43:53] [36m"GET /static/admin/css/base.css HTTP/1.1" 304 0[0m
[11/Sep/2024 08:43:53] [36m"GET /static/admin/js/theme.js HTTP/1.1" 304 0[0m
[11/Sep/2024 08:43:53] [36m"GET /static/admin/css/login.css HTTP/1.1" 304 0[0m
[11/Sep/2024 08:43:53] [36m"GET /static/admin/css/responsive.css HTTP/1.1" 304 0[0m
[11/Sep/2024 08:43:54] [m"GET /api/ HTTP/1.1" 200 0[0m
[11/Sep/2024 08:44:06] [m"GET /api/ HTTP/1.1" 200 0[0m
[11/Sep/2024 08:44:07] [m"GET /api/ HTTP/1.1" 200 0[0m
[11/Sep/2024 08:44:07] [m"GET /api/ HTTP/1.1" 200 0[0m
/Users/abdullaazimov/Desktop/PROJECTS/INSAN/base/views.py changed, reloading.
Watching for file changes with StatReloader
Performing system checks...

System check identified no issues (0 silenced).
September 11, 2024 - 08:44:07
Django version 5.1.1, using settings 'Insan.settings'
Starting development server at http://127.0.0.1:8000/
Quit the server with CONTROL-C.

[11/Sep/2024 12:29:15] [m"GET /api/ HTTP/1.1" 200 0[0m
/Users/abdullaazimov/Desktop/PROJECTS/INSAN/base/views.py changed, reloading.
Watching for file changes with StatReloader
Performing system checks...

System check identified no issues (0 silenced).
September 11, 2024 - 12:29:16
Django version 5.1.1, using settings 'Insan.settings'
Starting development server at http://127.0.0.1:8000/
Quit the server with CONTROL-C.

[11/Sep/2024 12:29:16] [m"GET /api/ HTTP/1.1" 200 0[0m
[11/Sep/2024 12:29:16] [m"GET /api/ HTTP/1.1" 200 0[0m
[11/Sep/2024 12:29:17] [m"GET /api/ HTTP/1.1" 200 0[0m
[11/Sep/2024 12:29:17] [m"GET /api/ HTTP/1.1" 200 0[0m
[11/Sep/2024 12:29:17] [m"GET /api/ HTTP/1.1" 200 0[0m
[11/Sep/2024 12:29:17] [m"GET /api/ HTTP/1.1" 200 0[0m
[11/Sep/2024 12:29:18] [m"GET /api/ HTTP/1.1" 200 0[0m
[11/Sep/2024 12:29:18] [m"GET /api/ HTTP/1.1" 200 0[0m
[11/Sep/2024 12:29:18] [m"GET /api/ HTTP/1.1" 200 0[0m
[11/Sep/2024 12:29:19] [m"GET /api/ HTTP/1.1" 200 0[0m
[11/Sep/2024 12:29:19] [m"GET /api/ HTTP/1.1" 200 0[0m
[11/Sep/2024 12:29:19] [m"GET /api/ HTTP/1.1" 200 0[0m
[11/Sep/2024 12:29:19] [m"GET /api/ HTTP/1.1" 200 0[0m
[11/Sep/2024 12:29:20] [m"GET /api/ HTTP/1.1" 200 0[0m
[11/Sep/2024 12:29:20] [m"GET /api/ HTTP/1.1" 200 0[0m
[11/Sep/2024 12:29:20] [m"GET /api/ HTTP/1.1" 200 0[0m
[11/Sep/2024 12:29:20] [m"GET /api/ HTTP/1.1" 200 0[0m
[11/Sep/2024 12:29:21] [m"GET /api/ HTTP/1.1" 200 0[0m
[11/Sep/2024 12:29:21] [m"GET /api/ HTTP/1.1" 200 0[0m
[11/Sep/2024 12:29:22] [m"GET /api/ HTTP/1.1" 200 0[0m
[11/Sep/2024 12:29:40] [m"GET /api/ HTTP/1.1" 200 0[0m
[11/Sep/2024 12:29:40] [m"GET /api/ HTTP/1.1" 200 0[0m
[11/Sep/2024 12:29:42] [m"GET /api/ HTTP/1.1" 200 0[0m
Not Found: /
[11/Sep/2024 12:29:44] [33m"GET / HTTP/1.1" 404 2303[0m
Not Found: /
[11/Sep/2024 12:29:44] [33m"GET / HTTP/1.1" 404 2303[0m
[11/Sep/2024 12:29:47] [32m"GET /admin/ HTTP/1.1" 302 0[0m
[11/Sep/2024 12:29:47] [m"GET /admin/login/?next=/admin/ HTTP/1.1" 200 4160[0m
[11/Sep/2024 12:29:47] [36m"GET /static/admin/css/base.css HTTP/1.1" 304 0[0m
[11/Sep/2024 12:29:47] [36m"GET /static/admin/js/theme.js HTTP/1.1" 304 0[0m
[11/Sep/2024 12:29:47] [36m"GET /static/admin/css/login.css HTTP/1.1" 304 0[0m
[11/Sep/2024 12:29:47] [36m"GET /static/admin/css/responsive.css HTTP/1.1" 304 0[0m
[11/Sep/2024 12:30:23] [32m"GET /admin/ HTTP/1.1" 302 0[0m
[11/Sep/2024 12:30:23] [m"GET /admin/login/?next=/admin/ HTTP/1.1" 200 4160[0m
[11/Sep/2024 12:30:28] [32m"POST /admin/login/?next=/admin/ HTTP/1.1" 302 0[0m
[11/Sep/2024 12:30:28] [m"GET /admin/ HTTP/1.1" 200 5860[0m
[11/Sep/2024 12:30:28] [m"GET /static/admin/css/dashboard.css HTTP/1.1" 200 441[0m
[11/Sep/2024 12:30:28] [m"GET /static/admin/img/icon-changelink.svg HTTP/1.1" 200 380[0m
[11/Sep/2024 12:30:28] [m"GET /static/admin/img/icon-addlink.svg HTTP/1.1" 200 331[0m
Not Found: /
[11/Sep/2024 12:30:34] [33m"GET / HTTP/1.1" 404 2303[0m
Not Found: /new
[11/Sep/2024 12:30:37] [33m"GET /new HTTP/1.1" 404 2330[0m
[11/Sep/2024 12:30:41] [32m"GET /api HTTP/1.1" 301 0[0m
[11/Sep/2024 12:30:41] [m"GET /api/ HTTP/1.1" 200 0[0m
[11/Sep/2024 12:31:06] [m"GET /api/ HTTP/1.1" 200 0[0m
[11/Sep/2024 12:31:06] [m"GET /api/ HTTP/1.1" 200 0[0m
/Users/abdullaazimov/Desktop/PROJECTS/INSAN/base/urls.py changed, reloading.
Watching for file changes with StatReloader
Performing system checks...

System check identified no issues (0 silenced).
September 11, 2024 - 12:31:07
Django version 5.1.1, using settings 'Insan.settings'
Starting development server at http://127.0.0.1:8000/
Quit the server with CONTROL-C.

[11/Sep/2024 12:31:10] [m"GET /api/frs HTTP/1.1" 200 0[0m
[11/Sep/2024 12:31:11] [m"GET /api/frs HTTP/1.1" 200 0[0m
[11/Sep/2024 12:31:12] [m"GET /api/frs HTTP/1.1" 200 0[0m
[11/Sep/2024 12:31:12] [m"GET /api/frs HTTP/1.1" 200 0[0m
Not Found: /api/
[11/Sep/2024 12:31:14] [33m"GET /api/ HTTP/1.1" 404 2438[0m
[11/Sep/2024 12:31:22] [m"GET /api/frs HTTP/1.1" 200 0[0m
[11/Sep/2024 12:31:45] [m"GET /api/frs HTTP/1.1" 200 0[0m
/Users/abdullaazimov/Desktop/PROJECTS/INSAN/base/urls.py changed, reloading.
Watching for file changes with StatReloader
Performing system checks...

System check identified no issues (0 silenced).
September 11, 2024 - 12:31:46
Django version 5.1.1, using settings 'Insan.settings'
Starting development server at http://127.0.0.1:8000/
Quit the server with CONTROL-C.

[11/Sep/2024 12:31:46] [m"GET /api/frs HTTP/1.1" 200 0[0m
[11/Sep/2024 12:31:47] [m"GET /api/frs HTTP/1.1" 200 0[0m
[11/Sep/2024 12:31:47] [m"GET /api/frs HTTP/1.1" 200 0[0m
[11/Sep/2024 12:31:48] [m"GET /api/frs HTTP/1.1" 200 0[0m
[11/Sep/2024 12:31:48] [m"GET /api/frs HTTP/1.1" 200 0[0m
[11/Sep/2024 12:31:54] [m"GET /api/frs HTTP/1.1" 200 0[0m
[11/Sep/2024 12:31:55] [m"GET /api/frs HTTP/1.1" 200 0[0m
[11/Sep/2024 12:31:55] [m"GET /api/frs HTTP/1.1" 200 0[0m
^C[1m[7m%[27m[1m[0m                                                                                                                                                                                [0m[27m[24m[J(venv) abdullaazimov@MacBook-Pro-Abdulla INSAN % [K[?2004hpython manage.py runserver[?2004l
Watching for file changes with StatReloader
Performing system checks...

System check identified no issues (0 silenced).
September 11, 2024 - 12:34:28
Django version 5.1.1, using settings 'Insan.settings'
Starting development server at http://127.0.0.1:8000/
Quit the server with CONTROL-C.

[11/Sep/2024 12:34:29] [m"GET /api/frs HTTP/1.1" 200 0[0m
[11/Sep/2024 12:34:30] [m"GET /api/frs HTTP/1.1" 200 0[0m
[11/Sep/2024 12:34:30] [m"GET /api/frs HTTP/1.1" 200 0[0m
[11/Sep/2024 12:34:30] [m"GET /api/frs HTTP/1.1" 200 0[0m
[11/Sep/2024 12:34:31] [m"GET /api/frs HTTP/1.1" 200 0[0m
[11/Sep/2024 12:34:31] [m"GET /api/frs HTTP/1.1" 200 0[0m
[11/Sep/2024 12:34:31] [m"GET /api/frs HTTP/1.1" 200 0[0m
/Users/abdullaazimov/Desktop/PROJECTS/INSAN/base/views.py changed, reloading.
Watching for file changes with StatReloader
Performing system checks...

System check identified no issues (0 silenced).
September 11, 2024 - 12:35:26
Django version 5.1.1, using settings 'Insan.settings'
Starting development server at http://127.0.0.1:8000/
Quit the server with CONTROL-C.

View has been called
[11/Sep/2024 12:35:26] [m"GET /api/frs HTTP/1.1" 200 12[0m
/Users/abdullaazimov/Desktop/PROJECTS/INSAN/base/views.py changed, reloading.
Watching for file changes with StatReloader
Performing system checks...

System check identified no issues (0 silenced).
September 11, 2024 - 12:35:33
Django version 5.1.1, using settings 'Insan.settings'
Starting development server at http://127.0.0.1:8000/
Quit the server with CONTROL-C.

/Users/abdullaazimov/Desktop/PROJECTS/INSAN/base/views.py changed, reloading.
Watching for file changes with StatReloader
Performing system checks...

System check identified no issues (0 silenced).
September 11, 2024 - 12:35:36
Django version 5.1.1, using settings 'Insan.settings'
Starting development server at http://127.0.0.1:8000/
Quit the server with CONTROL-C.

/Users/abdullaazimov/Desktop/PROJECTS/INSAN/base/views.py changed, reloading.
Watching for file changes with StatReloader
Performing system checks...

System check identified no issues (0 silenced).
September 11, 2024 - 12:35:58
Django version 5.1.1, using settings 'Insan.settings'
Starting development server at http://127.0.0.1:8000/
Quit the server with CONTROL-C.

[11/Sep/2024 12:35:58] [m"GET /api/frs HTTP/1.1" 200 12[0m
[11/Sep/2024 12:35:59] [m"GET /api/frs HTTP/1.1" 200 12[0m
[11/Sep/2024 12:35:59] [m"GET /api/frs HTTP/1.1" 200 12[0m
[11/Sep/2024 12:35:59] [m"GET /api/frs HTTP/1.1" 200 12[0m
[11/Sep/2024 12:35:59] [m"GET /api/frs HTTP/1.1" 200 12[0m
[11/Sep/2024 12:35:59] [m"GET /api/frs HTTP/1.1" 200 12[0m
Not Found: /
[11/Sep/2024 12:36:17] [33m"GET / HTTP/1.1" 404 2320[0m
Not Found: /favicon.ico
[11/Sep/2024 12:36:25] [33m"GET /favicon.ico HTTP/1.1" 404 2371[0m
Not Found: /
[11/Sep/2024 12:36:27] [33m"GET / HTTP/1.1" 404 2320[0m
Not Found: /favicon.ico
[11/Sep/2024 12:36:27] [33m"GET /favicon.ico HTTP/1.1" 404 2371[0m
[11/Sep/2024 12:36:41] [32m"GET /admin HTTP/1.1" 301 0[0m
[11/Sep/2024 12:36:41] [32m"GET /admin/ HTTP/1.1" 302 0[0m
[11/Sep/2024 12:36:41] [m"GET /admin/login/?next=/admin/ HTTP/1.1" 200 4160[0m
[11/Sep/2024 12:36:42] [m"GET /static/admin/css/dark_mode.css HTTP/1.1" 200 2804[0m
[11/Sep/2024 12:36:42] [m"GET /static/admin/js/nav_sidebar.js HTTP/1.1" 200 3063[0m
[11/Sep/2024 12:36:42] [m"GET /static/admin/css/nav_sidebar.css HTTP/1.1" 200 2810[0m
[11/Sep/2024 12:36:42] [m"GET /static/admin/js/theme.js HTTP/1.1" 200 1653[0m
[11/Sep/2024 12:36:42] [m"GET /static/admin/css/login.css HTTP/1.1" 200 951[0m
[11/Sep/2024 12:36:42] [m"GET /static/admin/css/base.css HTTP/1.1" 200 22092[0m
[11/Sep/2024 12:36:42] [m"GET /static/admin/css/responsive.css HTTP/1.1" 200 17972[0m
[11/Sep/2024 12:36:42] [32m"GET /admin/login/favicon.ico?next=/admin/ HTTP/1.1" 302 0[0m
[11/Sep/2024 12:36:43] [m"GET /admin/login/?next=/admin/login/favicon.ico%3Fnext%3D/admin/ HTTP/1.1" 200 4224[0m
Forbidden (Origin checking failed - https://c52d-31-40-24-84.ngrok-free.app does not match any trusted origins.): /admin/login/
[11/Sep/2024 12:36:56] [31;1m"POST /admin/login/?next=/admin/ HTTP/1.1" 403 2572[0m
[11/Sep/2024 12:36:56] [32m"GET /admin/login/favicon.ico?next=/admin/ HTTP/1.1" 302 0[0m
[11/Sep/2024 12:36:56] [m"GET /admin/login/?next=/admin/login/favicon.ico%3Fnext%3D/admin/ HTTP/1.1" 200 4224[0m
[11/Sep/2024 12:38:31] [m"GET /admin/login/?next=/admin/ HTTP/1.1" 200 4160[0m
Forbidden (Origin checking failed - https://c52d-31-40-24-84.ngrok-free.app does not match any trusted origins.): /admin/login/
[11/Sep/2024 12:38:32] [31;1m"POST /admin/login/?next=/admin/ HTTP/1.1" 403 2572[0m
[11/Sep/2024 12:38:32] [32m"GET /admin/login/favicon.ico?next=/admin/ HTTP/1.1" 302 0[0m
[11/Sep/2024 12:38:32] [m"GET /admin/login/?next=/admin/login/favicon.ico%3Fnext%3D/admin/ HTTP/1.1" 200 4224[0m
Forbidden (Origin checking failed - https://c52d-31-40-24-84.ngrok-free.app does not match any trusted origins.): /admin/login/
[11/Sep/2024 12:38:36] [31;1m"POST /admin/login/?next=/admin/ HTTP/1.1" 403 2572[0m
[11/Sep/2024 12:38:37] [32m"GET /admin/login/favicon.ico?next=/admin/ HTTP/1.1" 302 0[0m
[11/Sep/2024 12:38:37] [m"GET /admin/login/?next=/admin/login/favicon.ico%3Fnext%3D/admin/ HTTP/1.1" 200 4224[0m
/Users/abdullaazimov/Desktop/PROJECTS/INSAN/Insan/settings.py changed, reloading.
Watching for file changes with StatReloader
Performing system checks...

System check identified no issues (0 silenced).
September 11, 2024 - 12:38:40
Django version 5.1.1, using settings 'Insan.settings'
Starting development server at http://127.0.0.1:8000/
Quit the server with CONTROL-C.

/Users/abdullaazimov/Desktop/PROJECTS/INSAN/Insan/settings.py changed, reloading.
Watching for file changes with StatReloader
Performing system checks...

Exception in thread django-main-thread:
Traceback (most recent call last):
  File "/Library/Frameworks/Python.framework/Versions/3.10/lib/python3.10/threading.py", line 1016, in _bootstrap_inner
    self.run()
  File "/Library/Frameworks/Python.framework/Versions/3.10/lib/python3.10/threading.py", line 953, in run
    self._target(*self._args, **self._kwargs)
  File "/Users/abdullaazimov/Desktop/PROJECTS/INSAN/venv/lib/python3.10/site-packages/django/utils/autoreload.py", line 64, in wrapper
    fn(*args, **kwargs)
  File "/Users/abdullaazimov/Desktop/PROJECTS/INSAN/venv/lib/python3.10/site-packages/django/core/management/commands/runserver.py", line 134, in inner_run
    self.check(display_num_errors=True)
  File "/Users/abdullaazimov/Desktop/PROJECTS/INSAN/venv/lib/python3.10/site-packages/django/core/management/base.py", line 563, in check
    raise SystemCheckError(msg)
django.core.management.base.SystemCheckError: [31;1mSystemCheckError: System check identified some issues:
[0m
ERRORS:
[31;1m?: (4_0.E001) As of Django 4.0, the values in the CSRF_TRUSTED_ORIGINS setting must start with a scheme (usually http:// or https://) but found *. See the release notes for details.[0m

System check identified 1 issue (0 silenced).
^C[1m[7m%[27m[1m[0m                                                                                                                                                                                [0m[27m[24m[J(venv) abdullaazimov@MacBook-Pro-Abdulla INSAN % [K[?2004hcclear[?2004l
[3J[H[2J[1m[7m%[27m[1m[0m                                                                                                                                                                                [0m[27m[24m[J(venv) abdullaazimov@MacBook-Pro-Abdulla INSAN % [K[?2004hclearpython manage.py runserver[?2004l
Watching for file changes with StatReloader
Performing system checks...

System check identified no issues (0 silenced).
September 11, 2024 - 12:42:04
Django version 5.1.1, using settings 'Insan.settings'
Starting development server at http://127.0.0.1:8000/
Quit the server with CONTROL-C.

Not Found: /
[11/Sep/2024 12:42:06] [33m"GET / HTTP/1.1" 404 2303[0m
Not Found: /
[11/Sep/2024 12:42:21] [33m"GET / HTTP/1.1" 404 2320[0m
Not Found: /favicon.ico
[11/Sep/2024 12:42:22] [33m"GET /favicon.ico HTTP/1.1" 404 2371[0m
[11/Sep/2024 12:42:27] [32m"GET /admin HTTP/1.1" 301 0[0m
[11/Sep/2024 12:42:27] [32m"GET /admin/ HTTP/1.1" 302 0[0m
[11/Sep/2024 12:42:27] [m"GET /admin/login/?next=/admin/ HTTP/1.1" 200 4160[0m
[11/Sep/2024 12:42:27] [m"GET /static/admin/js/theme.js HTTP/1.1" 200 1653[0m
[11/Sep/2024 12:42:27] [m"GET /static/admin/css/nav_sidebar.css HTTP/1.1" 200 2810[0m
[11/Sep/2024 12:42:27] [m"GET /static/admin/css/dark_mode.css HTTP/1.1" 200 2804[0m
[11/Sep/2024 12:42:27] [m"GET /static/admin/css/base.css HTTP/1.1" 200 22092[0m
[11/Sep/2024 12:42:28] [m"GET /static/admin/css/responsive.css HTTP/1.1" 200 17972[0m
[11/Sep/2024 12:42:28] [m"GET /static/admin/css/login.css HTTP/1.1" 200 951[0m
[11/Sep/2024 12:42:28] [m"GET /static/admin/js/nav_sidebar.js HTTP/1.1" 200 3063[0m
Not Found: /
[11/Sep/2024 12:42:41] [33m"GET / HTTP/1.1" 404 2320[0m
Not Found: /favicon.ico
[11/Sep/2024 12:42:52] [33m"GET /favicon.ico HTTP/1.1" 404 2371[0m
Not Found: /
[11/Sep/2024 12:42:52] [33m"GET / HTTP/1.1" 404 2320[0m
Not Found: /favicon.ico
[11/Sep/2024 12:42:53] [33m"GET /favicon.ico HTTP/1.1" 404 2371[0m
[11/Sep/2024 12:43:10] [32m"GET /admin HTTP/1.1" 301 0[0m
[11/Sep/2024 12:43:10] [32m"GET /admin/ HTTP/1.1" 302 0[0m
[11/Sep/2024 12:43:11] [m"GET /admin/login/?next=/admin/ HTTP/1.1" 200 4160[0m
[11/Sep/2024 12:43:11] [m"GET /static/admin/css/dark_mode.css HTTP/1.1" 200 2804[0m
[11/Sep/2024 12:43:11] [m"GET /static/admin/js/nav_sidebar.js HTTP/1.1" 200 3063[0m
[11/Sep/2024 12:43:11] [m"GET /static/admin/js/theme.js HTTP/1.1" 200 1653[0m
[11/Sep/2024 12:43:11] [m"GET /static/admin/css/login.css HTTP/1.1" 200 951[0m
[11/Sep/2024 12:43:11] [m"GET /static/admin/css/nav_sidebar.css HTTP/1.1" 200 2810[0m
[11/Sep/2024 12:43:11] [m"GET /static/admin/css/base.css HTTP/1.1" 200 22092[0m
[11/Sep/2024 12:43:11] [m"GET /static/admin/css/responsive.css HTTP/1.1" 200 17972[0m
[11/Sep/2024 12:43:12] [32m"GET /admin/login/favicon.ico?next=/admin/ HTTP/1.1" 302 0[0m
[11/Sep/2024 12:43:12] [m"GET /admin/login/?next=/admin/login/favicon.ico%3Fnext%3D/admin/ HTTP/1.1" 200 4224[0m
[11/Sep/2024 12:43:29] [m"POST /admin/login/?next=/admin/ HTTP/1.1" 200 4328[0m
[11/Sep/2024 12:43:53] [32m"POST /admin/login/?next=/admin/ HTTP/1.1" 302 0[0m
[11/Sep/2024 12:43:53] [m"GET /admin/ HTTP/1.1" 200 5860[0m
[11/Sep/2024 12:43:54] [m"GET /static/admin/css/dashboard.css HTTP/1.1" 200 441[0m
[11/Sep/2024 12:43:54] [m"GET /static/admin/img/icon-addlink.svg HTTP/1.1" 200 331[0m
[11/Sep/2024 12:43:54] [m"GET /static/admin/img/icon-changelink.svg HTTP/1.1" 200 380[0m
[11/Sep/2024 12:44:05] [32m"POST /admin/login/?next=/admin/ HTTP/1.1" 302 0[0m
[11/Sep/2024 12:44:05] [m"GET /admin/ HTTP/1.1" 200 5860[0m
[11/Sep/2024 12:44:06] [m"GET /static/admin/css/dashboard.css HTTP/1.1" 200 441[0m
[11/Sep/2024 12:44:06] [m"GET /static/admin/img/icon-addlink.svg HTTP/1.1" 200 331[0m
[11/Sep/2024 12:44:06] [m"GET /static/admin/img/icon-changelink.svg HTTP/1.1" 200 380[0m
[11/Sep/2024 12:44:07] [32m"GET /admin/favicon.ico HTTP/1.1" 302 0[0m
[11/Sep/2024 12:44:07] [m"GET /admin/login/?next=/admin/favicon.ico HTTP/1.1" 200 4182[0m
Not Found: /
[11/Sep/2024 12:44:20] [33m"GET / HTTP/1.1" 404 2320[0m
Not Found: /api
[11/Sep/2024 12:44:24] [33m"GET /api HTTP/1.1" 404 2347[0m
Not Found: /api
[11/Sep/2024 12:44:29] [33m"GET /api HTTP/1.1" 404 2347[0m
Not Found: /api/
[11/Sep/2024 12:44:33] [33m"GET /api/ HTTP/1.1" 404 2455[0m
/Users/abdullaazimov/Desktop/PROJECTS/INSAN/Insan/settings.py changed, reloading.
Watching for file changes with StatReloader
Performing system checks...

System check identified no issues (0 silenced).
[31m
You have 4 unapplied migration(s). Your project may not work properly until you apply the migrations for app(s): authtoken.[0m
[31mRun 'python manage.py migrate' to apply them.[0m
September 11, 2024 - 13:57:25
Django version 5.1.1, using settings 'Insan.settings'
Starting development server at http://127.0.0.1:8000/
Quit the server with CONTROL-C.

/Users/abdullaazimov/Desktop/PROJECTS/INSAN/base/models.py changed, reloading.
Watching for file changes with StatReloader
Performing system checks...

Exception in thread django-main-thread:
Traceback (most recent call last):
  File "/Library/Frameworks/Python.framework/Versions/3.10/lib/python3.10/threading.py", line 1016, in _bootstrap_inner
    self.run()
  File "/Library/Frameworks/Python.framework/Versions/3.10/lib/python3.10/threading.py", line 953, in run
    self._target(*self._args, **self._kwargs)
  File "/Users/abdullaazimov/Desktop/PROJECTS/INSAN/venv/lib/python3.10/site-packages/django/utils/autoreload.py", line 64, in wrapper
    fn(*args, **kwargs)
  File "/Users/abdullaazimov/Desktop/PROJECTS/INSAN/venv/lib/python3.10/site-packages/django/core/management/commands/runserver.py", line 134, in inner_run
    self.check(display_num_errors=True)
  File "/Users/abdullaazimov/Desktop/PROJECTS/INSAN/venv/lib/python3.10/site-packages/django/core/management/base.py", line 563, in check
    raise SystemCheckError(msg)
django.core.management.base.SystemCheckError: [31;1mSystemCheckError: System check identified some issues:
[0m
ERRORS:
[31;1mauth.User.groups: (fields.E304) Reverse accessor 'Group.user_set' for 'auth.User.groups' clashes with reverse accessor for 'base.CustomUser.groups'.
	HINT: Add or change a related_name argument to the definition for 'auth.User.groups' or 'base.CustomUser.groups'.[0m
[31;1mauth.User.user_permissions: (fields.E304) Reverse accessor 'Permission.user_set' for 'auth.User.user_permissions' clashes with reverse accessor for 'base.CustomUser.user_permissions'.
	HINT: Add or change a related_name argument to the definition for 'auth.User.user_permissions' or 'base.CustomUser.user_permissions'.[0m
[31;1mbase.CustomUser.groups: (fields.E304) Reverse accessor 'Group.user_set' for 'base.CustomUser.groups' clashes with reverse accessor for 'auth.User.groups'.
	HINT: Add or change a related_name argument to the definition for 'base.CustomUser.groups' or 'auth.User.groups'.[0m
[31;1mbase.CustomUser.user_permissions: (fields.E304) Reverse accessor 'Permission.user_set' for 'base.CustomUser.user_permissions' clashes with reverse accessor for 'auth.User.user_permissions'.
	HINT: Add or change a related_name argument to the definition for 'base.CustomUser.user_permissions' or 'auth.User.user_permissions'.[0m

System check identified 4 issues (0 silenced).
/Users/abdullaazimov/Desktop/PROJECTS/INSAN/Insan/settings.py changed, reloading.
Watching for file changes with StatReloader
Exception in thread django-main-thread:
Traceback (most recent call last):
  File "/Users/abdullaazimov/Desktop/PROJECTS/INSAN/venv/lib/python3.10/site-packages/django/apps/registry.py", line 158, in get_app_config
    return self.app_configs[app_label]
KeyError: 'accounts'

During handling of the above exception, another exception occurred:

Traceback (most recent call last):
  File "/Users/abdullaazimov/Desktop/PROJECTS/INSAN/venv/lib/python3.10/site-packages/django/contrib/auth/__init__.py", line 188, in get_user_model
    return django_apps.get_model(settings.AUTH_USER_MODEL, require_ready=False)
  File "/Users/abdullaazimov/Desktop/PROJECTS/INSAN/venv/lib/python3.10/site-packages/django/apps/registry.py", line 208, in get_model
    app_config = self.get_app_config(app_label)
  File "/Users/abdullaazimov/Desktop/PROJECTS/INSAN/venv/lib/python3.10/site-packages/django/apps/registry.py", line 165, in get_app_config
    raise LookupError(message)
LookupError: No installed app with label 'accounts'.

During handling of the above exception, another exception occurred:

Traceback (most recent call last):
  File "/Library/Frameworks/Python.framework/Versions/3.10/lib/python3.10/threading.py", line 1016, in _bootstrap_inner
    self.run()
  File "/Library/Frameworks/Python.framework/Versions/3.10/lib/python3.10/threading.py", line 953, in run
    self._target(*self._args, **self._kwargs)
  File "/Users/abdullaazimov/Desktop/PROJECTS/INSAN/venv/lib/python3.10/site-packages/django/utils/autoreload.py", line 64, in wrapper
    fn(*args, **kwargs)
  File "/Users/abdullaazimov/Desktop/PROJECTS/INSAN/venv/lib/python3.10/site-packages/django/core/management/commands/runserver.py", line 126, in inner_run
    autoreload.raise_last_exception()
  File "/Users/abdullaazimov/Desktop/PROJECTS/INSAN/venv/lib/python3.10/site-packages/django/utils/autoreload.py", line 87, in raise_last_exception
    raise _exception[1]
  File "/Users/abdullaazimov/Desktop/PROJECTS/INSAN/venv/lib/python3.10/site-packages/django/core/management/__init__.py", line 394, in execute
    autoreload.check_errors(django.setup)()
  File "/Users/abdullaazimov/Desktop/PROJECTS/INSAN/venv/lib/python3.10/site-packages/django/utils/autoreload.py", line 64, in wrapper
    fn(*args, **kwargs)
  File "/Users/abdullaazimov/Desktop/PROJECTS/INSAN/venv/lib/python3.10/site-packages/django/__init__.py", line 24, in setup
    apps.populate(settings.INSTALLED_APPS)
  File "/Users/abdullaazimov/Desktop/PROJECTS/INSAN/venv/lib/python3.10/site-packages/django/apps/registry.py", line 124, in populate
    app_config.ready()
  File "/Users/abdullaazimov/Desktop/PROJECTS/INSAN/venv/lib/python3.10/site-packages/django/contrib/admin/apps.py", line 27, in ready
    self.module.autodiscover()
  File "/Users/abdullaazimov/Desktop/PROJECTS/INSAN/venv/lib/python3.10/site-packages/django/contrib/admin/__init__.py", line 52, in autodiscover
    autodiscover_modules("admin", register_to=site)
  File "/Users/abdullaazimov/Desktop/PROJECTS/INSAN/venv/lib/python3.10/site-packages/django/utils/module_loading.py", line 58, in autodiscover_modules
    import_module("%s.%s" % (app_config.name, module_to_search))
  File "/Library/Frameworks/Python.framework/Versions/3.10/lib/python3.10/importlib/__init__.py", line 126, in import_module
    return _bootstrap._gcd_import(name[level:], package, level)
  File "<frozen importlib._bootstrap>", line 1050, in _gcd_import
  File "<frozen importlib._bootstrap>", line 1027, in _find_and_load
  File "<frozen importlib._bootstrap>", line 1006, in _find_and_load_unlocked
  File "<frozen importlib._bootstrap>", line 688, in _load_unlocked
  File "<frozen importlib._bootstrap_external>", line 883, in exec_module
  File "<frozen importlib._bootstrap>", line 241, in _call_with_frames_removed
  File "/Users/abdullaazimov/Desktop/PROJECTS/INSAN/venv/lib/python3.10/site-packages/django/contrib/auth/admin.py", line 6, in <module>
    from django.contrib.auth.forms import (
  File "/Users/abdullaazimov/Desktop/PROJECTS/INSAN/venv/lib/python3.10/site-packages/django/contrib/auth/forms.py", line 19, in <module>
    UserModel = get_user_model()
  File "/Users/abdullaazimov/Desktop/PROJECTS/INSAN/venv/lib/python3.10/site-packages/django/contrib/auth/__init__.py", line 194, in get_user_model
    raise ImproperlyConfigured(
django.core.exceptions.ImproperlyConfigured: AUTH_USER_MODEL refers to model 'accounts.CustomUser' that has not been installed
/Users/abdullaazimov/Desktop/PROJECTS/INSAN/Insan/settings.py changed, reloading.
Watching for file changes with StatReloader
Exception in thread django-main-thread:
Traceback (most recent call last):
  File "/Users/abdullaazimov/Desktop/PROJECTS/INSAN/venv/lib/python3.10/site-packages/django/apps/registry.py", line 158, in get_app_config
    return self.app_configs[app_label]
KeyError: 'accounts'

During handling of the above exception, another exception occurred:

Traceback (most recent call last):
  File "/Users/abdullaazimov/Desktop/PROJECTS/INSAN/venv/lib/python3.10/site-packages/django/contrib/auth/__init__.py", line 188, in get_user_model
    return django_apps.get_model(settings.AUTH_USER_MODEL, require_ready=False)
  File "/Users/abdullaazimov/Desktop/PROJECTS/INSAN/venv/lib/python3.10/site-packages/django/apps/registry.py", line 208, in get_model
    app_config = self.get_app_config(app_label)
  File "/Users/abdullaazimov/Desktop/PROJECTS/INSAN/venv/lib/python3.10/site-packages/django/apps/registry.py", line 165, in get_app_config
    raise LookupError(message)
LookupError: No installed app with label 'accounts'.

During handling of the above exception, another exception occurred:

Traceback (most recent call last):
  File "/Library/Frameworks/Python.framework/Versions/3.10/lib/python3.10/threading.py", line 1016, in _bootstrap_inner
    self.run()
  File "/Library/Frameworks/Python.framework/Versions/3.10/lib/python3.10/threading.py", line 953, in run
    self._target(*self._args, **self._kwargs)
  File "/Users/abdullaazimov/Desktop/PROJECTS/INSAN/venv/lib/python3.10/site-packages/django/utils/autoreload.py", line 64, in wrapper
    fn(*args, **kwargs)
  File "/Users/abdullaazimov/Desktop/PROJECTS/INSAN/venv/lib/python3.10/site-packages/django/core/management/commands/runserver.py", line 126, in inner_run
    autoreload.raise_last_exception()
  File "/Users/abdullaazimov/Desktop/PROJECTS/INSAN/venv/lib/python3.10/site-packages/django/utils/autoreload.py", line 87, in raise_last_exception
    raise _exception[1]
  File "/Users/abdullaazimov/Desktop/PROJECTS/INSAN/venv/lib/python3.10/site-packages/django/core/management/__init__.py", line 394, in execute
    autoreload.check_errors(django.setup)()
  File "/Users/abdullaazimov/Desktop/PROJECTS/INSAN/venv/lib/python3.10/site-packages/django/utils/autoreload.py", line 64, in wrapper
    fn(*args, **kwargs)
  File "/Users/abdullaazimov/Desktop/PROJECTS/INSAN/venv/lib/python3.10/site-packages/django/__init__.py", line 24, in setup
    apps.populate(settings.INSTALLED_APPS)
  File "/Users/abdullaazimov/Desktop/PROJECTS/INSAN/venv/lib/python3.10/site-packages/django/apps/registry.py", line 124, in populate
    app_config.ready()
  File "/Users/abdullaazimov/Desktop/PROJECTS/INSAN/venv/lib/python3.10/site-packages/django/contrib/admin/apps.py", line 27, in ready
    self.module.autodiscover()
  File "/Users/abdullaazimov/Desktop/PROJECTS/INSAN/venv/lib/python3.10/site-packages/django/contrib/admin/__init__.py", line 52, in autodiscover
    autodiscover_modules("admin", register_to=site)
  File "/Users/abdullaazimov/Desktop/PROJECTS/INSAN/venv/lib/python3.10/site-packages/django/utils/module_loading.py", line 58, in autodiscover_modules
    import_module("%s.%s" % (app_config.name, module_to_search))
  File "/Library/Frameworks/Python.framework/Versions/3.10/lib/python3.10/importlib/__init__.py", line 126, in import_module
    return _bootstrap._gcd_import(name[level:], package